Workbook

Sheet Summary
A1: Summary by Module
A2: Source: Figma file 'Dentist' (https://www.figma.com/design/dAKa9xPhXAuRKat5jGS8Hx/Dentist), Page 1, as of Oct 11, 2026.
A4: Module ID | B4: Module | C4: Sub-modules | D4: Features | E4: Screens
A5: M00 | B5: Global / Shell | C5: =COUNTIFS('Module List'!$A:$A,"M00.*",'Module List'!$B:$B,"Sub-module") -> 1 | D5: =COUNTIFS('Module List'!$A:$A,"M00.*",'Module List'!$B:$B,"Feature") -> 5 | E5: =COUNTIF('Screen Inventory'!$B:$B,"M00") -> 0
A6: M01 | B6: Dashboard | C6: =COUNTIFS('Module List'!$A:$A,"M01.*",'Module List'!$B:$B,"Sub-module") -> 1 | D6: =COUNTIFS('Module List'!$A:$A,"M01.*",'Module List'!$B:$B,"Feature") -> 6 | E6: =COUNTIF('Screen Inventory'!$B:$B,"M01") -> 1
A7: M02 | B7: Appointments | C7: =COUNTIFS('Module List'!$A:$A,"M02.*",'Module List'!$B:$B,"Sub-module") -> 4 | D7: =COUNTIFS('Module List'!$A:$A,"M02.*",'Module List'!$B:$B,"Feature") -> 20 | E7: =COUNTIF('Screen Inventory'!$B:$B,"M02") -> 26
A8: M03 | B8: Patients | C8: =COUNTIFS('Module List'!$A:$A,"M03.*",'Module List'!$B:$B,"Sub-module") -> 10 | D8: =COUNTIFS('Module List'!$A:$A,"M03.*",'Module List'!$B:$B,"Feature") -> 35 | E8: =COUNTIF('Screen Inventory'!$B:$B,"M03") -> 39
A9: M04 | B9: Reports | C9: =COUNTIFS('Module List'!$A:$A,"M04.*",'Module List'!$B:$B,"Sub-module") -> 2 | D9: =COUNTIFS('Module List'!$A:$A,"M04.*",'Module List'!$B:$B,"Feature") -> 6 | E9: =COUNTIF('Screen Inventory'!$B:$B,"M04") -> 6
A10: M05 | B10: Account | C10: =COUNTIFS('Module List'!$A:$A,"M05.*",'Module List'!$B:$B,"Sub-module") -> 2 | D10: =COUNTIFS('Module List'!$A:$A,"M05.*",'Module List'!$B:$B,"Feature") -> 11 | E10: =COUNTIF('Screen Inventory'!$B:$B,"M05") -> 11
B11: Total | C11: =SUM(C5:C10) -> 20 | D11: =SUM(D5:D10) -> 83 | E11: =SUM(E5:E10) -> 83

Sheet Module Map
A1: Oralux Dentist Portal — Module Map
A2: Source: Figma file 'Dentist' (https://www.figma.com/design/dAKa9xPhXAuRKat5jGS8Hx/Dentist), Page 1, as of Oct 11, 2026. Read left to right: Module → Sub-module → Feature.
A4: Module | B4: Sub-module | C4: Feature | D4: Screens | E4: Figma
A5: M00 Global / Shell | B5: M00.01 Navigation & Layout | C5: M00.01.01 Org / clinic switcher | D5: =COUNTIF('Screen Inventory'!$F:$F,"M00.01.01") -> 0
C6: M00.01.02 Sidebar menu | D6: =COUNTIF('Screen Inventory'!$F:$F,"M00.01.02") -> 0
C7: M00.01.03 Global search (⌘K) | D7: =COUNTIF('Screen Inventory'!$F:$F,"M00.01.03") -> 0
C8: M00.01.04 Notifications | D8: =COUNTIF('Screen Inventory'!$F:$F,"M00.01.04") -> 0
C9: M00.01.05 User menu | D9: =COUNTIF('Screen Inventory'!$F:$F,"M00.01.05") -> 0
A10: M01 Dashboard | B10: M01.01 Overview | C10: M01.01.01 Greeting & day summary | D10: =COUNTIF('Screen Inventory'!$F:$F,"M01.01.01") -> 1 | E10: Open
C11: M01.01.02 Today's schedule | D11: =COUNTIF('Screen Inventory'!$F:$F,"M01.01.02") -> 0
C12: M01.01.03 Up next card | D12: =COUNTIF('Screen Inventory'!$F:$F,"M01.01.03") -> 0
C13: M01.01.04 Appointment requests widget | D13: =COUNTIF('Screen Inventory'!$F:$F,"M01.01.04") -> 0
C14: M01.01.05 Patients seen per month | D14: =COUNTIF('Screen Inventory'!$F:$F,"M01.01.05") -> 0
C15: M01.01.06 Recent patients | D15: =COUNTIF('Screen Inventory'!$F:$F,"M01.01.06") -> 0
A16: M02 Appointments | B16: M02.01 Calendar Views | C16: M02.01.01 Day view | D16: =COUNTIF('Screen Inventory'!$F:$F,"M02.01.01") -> 2 | E16: Open
C17: M02.01.02 Date filter | D17: =COUNTIF('Screen Inventory'!$F:$F,"M02.01.02") -> 1 | E17: Open
C18: M02.01.03 Week view | D18: =COUNTIF('Screen Inventory'!$F:$F,"M02.01.03") -> 1 | E18: Open
C19: M02.01.04 Month view | D19: =COUNTIF('Screen Inventory'!$F:$F,"M02.01.04") -> 1 | E19: Open
C20: M02.01.05 Filters & toolbar | D20: =COUNTIF('Screen Inventory'!$F:$F,"M02.01.05") -> 0
C21: M02.01.06 Status legend & summary | D21: =COUNTIF('Screen Inventory'!$F:$F,"M02.01.06") -> 0
B22: M02.02 Appointment Details | C22: M02.02.01 View details | D22: =COUNTIF('Screen Inventory'!$F:$F,"M02.02.01") -> 1 | E22: Open
C23: M02.02.02 Status states | D23: =COUNTIF('Screen Inventory'!$F:$F,"M02.02.02") -> 6 | E23: Open
C24: M02.02.03 Reschedule | D24: =COUNTIF('Screen Inventory'!$F:$F,"M02.02.03") -> 1 | E24: Open
C25: M02.02.04 Cancel appointment | D25: =COUNTIF('Screen Inventory'!$F:$F,"M02.02.04") -> 1 | E25: Open
C26: M02.02.05 More actions menu | D26: =COUNTIF('Screen Inventory'!$F:$F,"M02.02.05") -> 1 | E26: Open
C27: M02.02.06 Change procedure | D27: =COUNTIF('Screen Inventory'!$F:$F,"M02.02.06") -> 1 | E27: Open
C28: M02.02.07 Last visit history | D28: =COUNTIF('Screen Inventory'!$F:$F,"M02.02.07") -> 1 | E28: Open
B29: M02.03 Add Appointment | C29: M02.03.01 Select patient | D29: =COUNTIF('Screen Inventory'!$F:$F,"M02.03.01") -> 3 | E29: Open
C30: M02.03.02 Select procedure & schedule | D30: =COUNTIF('Screen Inventory'!$F:$F,"M02.03.02") -> 1 | E30: Open
C31: M02.03.03 All procedures list | D31: =COUNTIF('Screen Inventory'!$F:$F,"M02.03.03") -> 1 | E31: Open
C32: M02.03.04 Review & confirm | D32: =COUNTIF('Screen Inventory'!$F:$F,"M02.03.04") -> 1 | E32: Open
C33: M02.03.05 Booking confirmation | D33: =COUNTIF('Screen Inventory'!$F:$F,"M02.03.05") -> 1 | E33: Open
B34: M02.04 Appointment Requests | C34: M02.04.01 Requests drawer | D34: =COUNTIF('Screen Inventory'!$F:$F,"M02.04.01") -> 1 | E34: Open
C35: M02.04.02 Request details | D35: =COUNTIF('Screen Inventory'!$F:$F,"M02.04.02") -> 1 | E35: Open
A36: M03 Patients | B36: M03.01 Patient List | C36: M03.01.01 Patient list | D36: =COUNTIF('Screen Inventory'!$F:$F,"M03.01.01") -> 1 | E36: Open
B37: M03.02 Add Patient | C37: M03.02.01 Add patient form | D37: =COUNTIF('Screen Inventory'!$F:$F,"M03.02.01") -> 1 | E37: Open
C38: M03.02.02 Add success | D38: =COUNTIF('Screen Inventory'!$F:$F,"M03.02.02") -> 1 | E38: Open
C39: M03.02.03 Duplicate detection | D39: =COUNTIF('Screen Inventory'!$F:$F,"M03.02.03") -> 1 | E39: Open
C40: M03.02.04 Merge records | D40: =COUNTIF('Screen Inventory'!$F:$F,"M03.02.04") -> 1 | E40: Open
C41: M03.02.05 Merge success | D41: =COUNTIF('Screen Inventory'!$F:$F,"M03.02.05") -> 1 | E41: Open
...

Sheet Module List
A1: Oralux Dentist Portal — Module List
A2: Source: Figma file 'Dentist' (https://www.figma.com/design/dAKa9xPhXAuRKat5jGS8Hx/Dentist), Page 1, as of Oct 11, 2026.
A4: ID | B4: Level | C4: Module | D4: Sub-module | E4: Feature | F4: Description | G4: Screens | H4: Figma link | I4: Notes
A5: M00 | B5: Module | C5: Global / Shell | F5: App frame shared by every screen: navigation, search and user context. | G5: =COUNTIF('Screen Inventory'!$B:$B,"M00") -> 0
A6: M00.01 | B6: Sub-module | C6: Global / Shell | D6: Navigation & Layout | F6: Persistent sidebar and top bar. | G6: =COUNTIF('Screen Inventory'!$D:$D,"M00.01") -> 0
A7: M00.01.01 | B7: Feature | C7: Global / Shell | D7: Navigation & Layout | E7: Org / clinic switcher | F7: Clinic logo and name with 'Powered by oralux'; collapse-panel toggle. | G7: =COUNTIF('Screen Inventory'!$F:$F,"M00.01.01") -> 0 | I7: Shared UI — no dedicated frame
A8: M00.01.02 | B8: Feature | C8: Global / Shell | D8: Navigation & Layout | E8: Sidebar menu | F8: Links to Dashboard, Appointments (Schedule), Patients and Reports. | G8: =COUNTIF('Screen Inventory'!$F:$F,"M00.01.02") -> 0 | I8: Shared UI — no dedicated frame
A9: M00.01.03 | B9: Feature | C9: Global / Shell | D9: Navigation & Layout | E9: Global search (⌘K) | F9: Search patients and records from anywhere. | G9: =COUNTIF('Screen Inventory'!$F:$F,"M00.01.03") -> 0 | I9: Shared UI — no dedicated frame
A10: M00.01.04 | B10: Feature | C10: Global / Shell | D10: Navigation & Layout | E10: Notifications | F10: Bell with unread count badge. | G10: =COUNTIF('Screen Inventory'!$F:$F,"M00.01.04") -> 0 | I10: Shared UI — no dedicated frame
A11: M00.01.05 | B11: Feature | C11: Global / Shell | D11: Navigation & Layout | E11: User menu | F11: Logged-in dentist name, email and avatar; entry to Account. | G11: =COUNTIF('Screen Inventory'!$F:$F,"M00.01.05") -> 0 | I11: Shared UI — no dedicated frame
A12: M01 | B12: Module | C12: Dashboard | F12: Dentist landing page summarising today's work. | G12: =COUNTIF('Screen Inventory'!$B:$B,"M01") -> 1
A13: M01.01 | B13: Sub-module | C13: Dashboard | D13: Overview | F13: Daily summary for the logged-in dentist. | G13: =COUNTIF('Screen Inventory'!$D:$D,"M01.01") -> 1
A14: M01.01.01 | B14: Feature | C14: Dashboard | D14: Overview | E14: Greeting & day summary | F14: Greeting, date and number of appointments today. | G14: =COUNTIF('Screen Inventory'!$F:$F,"M01.01.01") -> 1 | H14: Open
A15: M01.01.02 | B15: Feature | C15: Dashboard | D15: Overview | E15: Today's schedule | F15: Timeline of today's appointments with status; next free slot; View all. | G15: =COUNTIF('Screen Inventory'!$F:$F,"M01.01.02") -> 0 | I15: Shared UI — no dedicated frame
A16: M01.01.03 | B16: Feature | C16: Dashboard | D16: Overview | E16: Up next card | F16: Next patient in N minutes with procedure/tooth; View patient / Dental chart shortcuts. | G16: =COUNTIF('Screen Inventory'!$F:$F,"M01.01.03") -> 0 | I16: Shared UI — no dedicated frame
A17: M01.01.04 | B17: Feature | C17: Dashboard | D17: Overview | E17: Appointment requests widget | F17: Pending requests with Accept / Decline. | G17: =COUNTIF('Screen Inventory'!$F:$F,"M01.01.04") -> 0 | I17: Shared UI — no dedicated frame
A18: M01.01.05 | B18: Feature | C18: Dashboard | D18: Overview | E18: Patients seen per month | F18: Bar chart of the last 6 months with % change. | G18: =COUNTIF('Screen Inventory'!$F:$F,"M01.01.05") -> 0 | I18: Shared UI — no dedicated frame
A19: M01.01.06 | B19: Feature | C19: Dashboard | D19: Overview | E19: Recent patients | F19: Patients from the most recent visits. | G19: =COUNTIF('Screen Inventory'!$F:$F,"M01.01.06") -> 0 | I19: Shared UI — no dedicated frame
A20: M02 | B20: Module | C20: Appointments | F20: Clinic schedule: calendar views, booking, request handling and appointment lifecycle. | G20: =COUNTIF('Screen Inventory'!$B:$B,"M02") -> 26
A21: M02.01 | B21: Sub-module | C21: Appointments | D21: Calendar Views | F21: Day, week and month calendar of appointments. | G21: =COUNTIF('Screen Inventory'!$D:$D,"M02.01") -> 5
A22: M02.01.01 | B22: Feature | C22: Appointments | D22: Calendar Views | E22: Day view | F22: Hourly timeline per dentist with status counts, Next up, and the requests panel. | G22: =COUNTIF('Screen Inventory'!$F:$F,"M02.01.01") -> 2 | H22: Open
A23: M02.01.02 | B23: Feature | C23: Appointments | D23: Calendar Views | E23: Date filter | F23: Date picker to jump to a specific day. | G23: =COUNTIF('Screen Inventory'!$F:$F,"M02.01.02") -> 1 | H23: Open
A24: M02.01.03 | B24: Feature | C24: Appointments | D24: Calendar Views | E24: Week view | F24: Week grid with appointment counts per day. | G24: =COUNTIF('Screen Inventory'!$F:$F,"M02.01.03") -> 1 | H24: Open
A25: M02.01.04 | B25: Feature | C25: Appointments | D25: Calendar Views | E25: Month view | F25: Month grid of appointments. | G25: =COUNTIF('Screen Inventory'!$F:$F,"M02.01.04") -> 1 | H25: Open
A26: M02.01.05 | B26: Feature | C26: Appointments | D26: Calendar Views | E26: Filters & toolbar | F26: Today, treatment filter, chair filter, Day/Week/Month toggle, Full screen, New appointment. | G26: =COUNTIF('Screen Inventory'!$F:$F,"M02.01.05") -> 0 | I26: Shared UI — no dedicated frame
A27: M02.01.06 | B27: Feature | C27: Appointments | D27: Calendar Views | E27: Status legend & summary | F27: Confirmed, Pending, Rescheduled, Cancelled, Completed, In chair, Checked in, No-show. | G27: =COUNTIF('Screen Inventory'!$F:$F,"M02.01.06") -> 0 | I27: Shared UI — no dedicated frame
A28: M02.02 | B28: Sub-module | C28: Appointments | D28: Appointment Details | F28: Modal to view and act on a single appointment. | G28: =COUNTIF('Screen Inventory'!$D:$D,"M02.02") -> 12
A29: M02.02.01 | B29: Feature | C29: Appointments | D29: Appointment Details | E29: View details | F29: Appointment details modal opened from the calendar. | G29: =COUNTIF('Screen Inventory'!$F:$F,"M02.02.01") -> 1 | H29: Open
A30: M02.02.02 | B30: Feature | C30: Appointments | D30: Appointment Details | E30: Status states | F30: Details modal for Pending, Confirmed, Rescheduled, Cancelled and Completed. | G30: =COUNTIF('Screen Inventory'!$F:$F,"M02.02.02") -> 6 | H30: Open
A31: M02.02.03 | B31: Feature | C31: Appointments | D31: Appointment Details | E31: Reschedule | F31: Pick a new date and time for an appointment. | G31: =COUNTIF('Screen Inventory'!$F:$F,"M02.02.03") -> 1 | H31: Open
A32: M02.02.04 | B32: Feature | C32: Appointments | D32: Appointment Details | E32: Cancel appointment | F32: Confirmation dialog for cancelling. | G32: =COUNTIF('Screen Inventory'!$F:$F,"M02.02.04") -> 1 | H32: Open
A33: M02.02.05 | B33: Feature | C33: Appointments | D33: Appointment Details | E33: More actions menu | F33: Overflow actions on a confirmed appointment. | G33: =COUNTIF('Screen Inventory'!$F:$F,"M02.02.05") -> 1 | H33: Open
A34: M02.02.06 | B34: Feature | C34: Appointments | D34: Appointment Details | E34: Change procedure | F34: Multi-select to change the booked procedures. | G34: =COUNTIF('Screen Inventory'!$F:$F,"M02.02.06") -> 1 | H34: Open
A35: M02.02.07 | B35: Feature | C35: Appointments | D35: Appointment Details | E35: Last visit history | F35: Expandable summary of the patient's last visit. | G35: =COUNTIF('Screen Inventory'!$F:$F,"M02.02.07") -> 1 | H35: Open
A36: M02.03 | B36: Sub-module | C36: Appointments | D36: Add Appointment | F36: Step-by-step booking flow. | G36: =COUNTIF('Screen Inventory'!$D:$D,"M02.03") -> 7
A37: M02.03.01 | B37: Feature | C37: Appointments | D37: Add Appointment | E37: Select patient | F37: Search and pick a patient (empty, dropdown and selected states). | G37: =COUNTIF('Screen Inventory'!$F:$F,"M02.03.01") -> 3 | H37: Open
A38: M02.03.02 | B38: Feature | C38: Appointments | D38: Add Appointment | E38: Select procedure & schedule | F38: Choose procedures, dentist, date and time. | G38: =COUNTIF('Screen Inventory'!$F:$F,"M02.03.02") -> 1 | H38: Open
A39: M02.03.03 | B39: Feature | C39: Appointments | D39: Add Appointment | E39: All procedures list | F39: Browse the full procedure catalogue. | G39: =COUNTIF('Screen Inventory'!$F:$F,"M02.03.03") -> 1 | H39: Open
A40: M02.03.04 | B40: Feature | C40: Appointments | D40: Add Appointment | E40: Review & confirm | F40: Summary before booking. | G40: =COUNTIF('Screen Inventory'!$F:$F,"M02.03.04") -> 1 | H40: Open
A41: M02.03.05 | B41: Feature | C41: Appointments | D41: Add Appointment | E41: Booking confirmation | F41: Success state after booking. | G41: =COUNTIF('Screen Inventory'!$F:$F,"M02.03.05") -> 1 | H41: Open
...

Sheet Screen Inventory
A1: Screen Inventory (Figma frames)
A2: Source: Figma file 'Dentist' (https://www.figma.com/design/dAKa9xPhXAuRKat5jGS8Hx/Dentist), Page 1, as of Oct 11, 2026. One row per frame; modal states inside the 'Appointment details modal · All statuses' section are listed individually.
A4: # | B4: Module ID | C4: Module | D4: Sub-module ID | E4: Sub-module | F4: Feature ID | G4: Feature | H4: Figma frame name | I4: Figma link
A5: 1 | B5: M01 | C5: Dashboard | D5: M01.01 | E5: Overview | F5: M01.01.01 | G5: Greeting & day summary | H5: Dashboard — Dentist · Overview | I5: Open
A6: 2 | B6: M02 | C6: Appointments | D6: M02.01 | E6: Calendar Views | F6: M02.01.01 | G6: Day view | H6: Appointments - Day | I6: Open
A7: 3 | B7: M02 | C7: Appointments | D7: M02.01 | E7: Calendar Views | F7: M02.01.01 | G7: Day view | H7: Appointments - Day | I7: Open
A8: 4 | B8: M02 | C8: Appointments | D8: M02.01 | E8: Calendar Views | F8: M02.01.02 | G8: Date filter | H8: Appointments - Day · Date filter | I8: Open
A9: 5 | B9: M02 | C9: Appointments | D9: M02.01 | E9: Calendar Views | F9: M02.01.03 | G9: Week view | H9: Appointments - Week | I9: Open
A10: 6 | B10: M02 | C10: Appointments | D10: M02.01 | E10: Calendar Views | F10: M02.01.04 | G10: Month view | H10: Appointments - Month | I10: Open
A11: 7 | B11: M02 | C11: Appointments | D11: M02.02 | E11: Appointment Details | F11: M02.02.01 | G11: View details | H11: Appointments - Day · Details · Modal | I11: Open
A12: 8 | B12: M02 | C12: Appointments | D12: M02.02 | E12: Appointment Details | F12: M02.02.02 | G12: Status states | H12: Details modal · Pending | I12: Open
A13: 9 | B13: M02 | C13: Appointments | D13: M02.02 | E13: Appointment Details | F13: M02.02.02 | G13: Status states | H13: Details modal · Confirmed | I13: Open
A14: 10 | B14: M02 | C14: Appointments | D14: M02.02 | E14: Appointment Details | F14: M02.02.02 | G14: Status states | H14: Details modal · Rescheduled | I14: Open
A15: 11 | B15: M02 | C15: Appointments | D15: M02.02 | E15: Appointment Details | F15: M02.02.02 | G15: Status states | H15: Details modal · Cancelled | I15: Open
A16: 12 | B16: M02 | C16: Appointments | D16: M02.02 | E16: Appointment Details | F16: M02.02.02 | G16: Status states | H16: Details modal · Completed | I16: Open
... A87: 83 | B87: M05 | C87: Account | D87: M05.02 | E87: My Signature | F87: M05.02.05 | G87: Remove signature | H87: Profile — Account · My signature · Remove confirmation | I87: Open
