Workbook

Sheet Module Timeline
A1: Module Timeline
A2: Start and end per module, rolled up from the Dev Task List. Gantt bars are by week (week starting Monday).
A4: Module ID | B4: Module | C4: Track | D4: Starts after | E4: Planned start | F4: Planned end | G4: Working days | H4: Features | I4: Screens | J4: Done | K4: % done | M4: =ProjectStart-WEEKDAY(ProjectStart,3)+7*0 -> 46314 | N4: =ProjectStart-WEEKDAY(ProjectStart,3)+7*1 -> 46321 | O4: =ProjectStart-WEEKDAY(ProjectStart,3)+7*2 -> 46328 | P4: =ProjectStart-WEEKDAY(ProjectStart,3)+7*3 -> 46335 | Q4: =ProjectStart-WEEKDAY(ProjectStart,3)+7*4 -> 46342 | R4: =ProjectStart-WEEKDAY(ProjectStart,3)+7*5 -> 46349 | S4: =ProjectStart-WEEKDAY(ProjectStart,3)+7*6 -> 46356 | T4: =ProjectStart-WEEKDAY(ProjectStart,3)+7*7 -> 46363 | U4: =ProjectStart-WEEKDAY(ProjectStart,3)+7*8 -> 46370 | V4: =ProjectStart-WEEKDAY(ProjectStart,3)+7*9 -> 46377 | W4: =ProjectStart-WEEKDAY(ProjectStart,3)+7*10 -> 46384 | X4: =ProjectStart-WEEKDAY(ProjectStart,3)+7*11 -> 46391 | Y4: =ProjectStart-WEEKDAY(ProjectStart,3)+7*12 -> 46398 | Z4: =ProjectStart-WEEKDAY(ProjectStart,3)+7*13 -> 46405 | AA4: =ProjectStart-WEEKDAY(ProjectStart,3)+7*14 -> 46412 | AB4: =ProjectStart-WEEKDAY(ProjectStart,3)+7*15 -> 46419 | AC4: =ProjectStart-WEEKDAY(ProjectStart,3)+7*16 -> 46426 | AD4: =ProjectStart-WEEKDAY(ProjectStart,3)+7*17 -> 46433 | AE4: =ProjectStart-WEEKDAY(ProjectStart,3)+7*18 -> 46440 | AF4: =ProjectStart-WEEKDAY(ProjectStart,3)+7*19 -> 46447 | AG4: =ProjectStart-WEEKDAY(ProjectStart,3)+7*20 -> 46454 | AH4: =ProjectStart-WEEKDAY(ProjectStart,3)+7*21 -> 46461 | AI4: =ProjectStart-WEEKDAY(ProjectStart,3)+7*22 -> 46468 | AJ4: =ProjectStart-WEEKDAY(ProjectStart,3)+7*23 -> 46475 | AK4: =ProjectStart-WEEKDAY(ProjectStart,3)+7*24 -> 46482 | AL4: =ProjectStart-WEEKDAY(ProjectStart,3)+7*25 -> 46489 | AM4: =ProjectStart-WEEKDAY(ProjectStart,3)+7*26 -> 46496 | AN4: =ProjectStart-WEEKDAY(ProjectStart,3)+7*27 -> 46503 | AO4: =ProjectStart-WEEKDAY(ProjectStart,3)+7*28 -> 46510 | AP4: =ProjectStart-WEEKDAY(ProjectStart,3)+7*29 -> 46517
A5: M00 | B5: Global / Shell | C5: Track A | D5: Project start | E5: =WORKDAY(ProjectStart-1,1,Holidays) -> 46314 | F5: =_xlfn.MAXIFS('Dev Task List'!$L:$L,'Dev Task List'!$B:$B,A5) -> 46324 | G5: =NETWORKDAYS(E5,F5,Holidays) -> 9 | H5: =COUNTIF('Dev Task List'!$B:$B,A5) -> 5 | I5: =SUMIF('Dev Task List'!$B:$B,A5,'Dev Task List'!$G:$G) -> 0 | J5: =COUNTIFS('Dev Task List'!$B:$B,A5,'Dev Task List'!$N:$N,"Done") -> 0 | K5: =IF(H5=0,0,J5/H5) -> 0 | M5: =IF(AND($E5<=M$4+6,$F5>=M$4),1,0) -> 1 | N5: =IF(AND($E5<=N$4+6,$F5>=N$4),1,0) -> 1 | O5: =IF(AND($E5<=O$4+6,$F5>=O$4),1,0) -> 0 | P5: =IF(AND($E5<=P$4+6,$F5>=P$4),1,0) -> 0 | Q5: =IF(AND($E5<=Q$4+6,$F5>=Q$4),1,0) -> 0 | R5: =IF(AND($E5<=R$4+6,$F5>=R$4),1,0) -> 0 | S5: =IF(AND($E5<=S$4+6,$F5>=S$4),1,0) -> 0 | T5: =IF(AND($E5<=T$4+6,$F5>=T$4),1,0) -> 0 | ... AP5: =IF(AND($E5<=AP$4+6,$F5>=AP$4),1,0) -> 0
A6: M02 | B6: Appointments | C6: Track A | D6: M00 Global / Shell | E6: =WORKDAY(F5,1,Holidays) -> 46325 | F6: =_xlfn.MAXIFS('Dev Task List'!$L:$L,'Dev Task List'!$B:$B,A6) -> 46385 | G6: =NETWORKDAYS(E6,F6,Holidays) -> 38 | H6: =COUNTIF('Dev Task List'!$B:$B,A6) -> 20 | I6: =SUMIF('Dev Task List'!$B:$B,A6,'Dev Task List'!$G:$G) -> 26 | J6: =COUNTIFS('Dev Task List'!$B:$B,A6,'Dev Task List'!$N:$N,"Done") -> 0 | K6: =IF(H6=0,0,J6/H6) -> 0 | M6: =IF(AND($E6<=M$4+6,$F6>=M$4),1,0) -> 0 | N6: =IF(AND($E6<=N$4+6,$F6>=N$4),1,0) -> 1 | O6: =IF(AND($E6<=O$4+6,$F6>=O$4),1,0) -> 1 | P6: =IF(AND($E6<=P$4+6,$F6>=P$4),1,0) -> 1 | Q6: =IF(AND($E6<=Q$4+6,$F6>=Q$4),1,0) -> 1 | R6: =IF(AND($E6<=R$4+6,$F6>=R$4),1,0) -> 1 | S6: =IF(AND($E6<=S$4+6,$F6>=S$4),1,0) -> 1 | T6: =IF(AND($E6<=T$4+6,$F6>=T$4),1,0) -> 1 | ... AP6: =IF(AND($E6<=AP$4+6,$F6>=AP$4),1,0) -> 0
A7: M03 | B7: Patients | C7: Track B | D7: M00 Global / Shell | E7: =WORKDAY(F5,1,Holidays) -> 46325 | F7: =_xlfn.MAXIFS('Dev Task List'!$L:$L,'Dev Task List'!$B:$B,A7) -> 46457 | G7: =NETWORKDAYS(E7,F7,Holidays) -> 86 | H7: =COUNTIF('Dev Task List'!$B:$B,A7) -> 40 | I7: =SUMIF('Dev Task List'!$B:$B,A7,'Dev Task List'!$G:$G) -> 45 | J7: =COUNTIFS('Dev Task List'!$B:$B,A7,'Dev Task List'!$N:$N,"Done") -> 0 | K7: =IF(H7=0,0,J7/H7) -> 0 | M7: =IF(AND($E7<=M$4+6,$F7>=M$4),1,0) -> 0 | N7: =IF(AND($E7<=N$4+6,$F7>=N$4),1,0) -> 1 | O7: =IF(AND($E7<=O$4+6,$F7>=O$4),1,0) -> 1 | P7: =IF(AND($E7<=P$4+6,$F7>=P$4),1,0) -> 1 | Q7: =IF(AND($E7<=Q$4+6,$F7>=Q$4),1,0) -> 1 | R7: =IF(AND($E7<=R$4+6,$F7>=R$4),1,0) -> 1 | S7: =IF(AND($E7<=S$4+6,$F7>=S$4),1,0) -> 1 | T7: =IF(AND($E7<=T$4+6,$F7>=T$4),1,0) -> 1 | ... AP7: =IF(AND($E7<=AP$4+6,$F7>=AP$4),1,0) -> 0
A8: M05 | B8: Account | C8: Track C | D8: M00 Global / Shell | E8: =WORKDAY(F5,1,Holidays) -> 46325 | F8: =_xlfn.MAXIFS('Dev Task List'!$L:$L,'Dev Task List'!$B:$B,A8) -> 46343 | G8: =NETWORKDAYS(E8,F8,Holidays) -> 12 | H8: =COUNTIF('Dev Task List'!$B:$B,A8) -> 11 | I8: =SUMIF('Dev Task List'!$B:$B,A8,'Dev Task List'!$G:$G) -> 11 | J8: =COUNTIFS('Dev Task List'!$B:$B,A8,'Dev Task List'!$N:$N,"Done") -> 0 | K8: =IF(H8=0,0,J8/H8) -> 0 | M8: =IF(AND($E8<=M$4+6,$F8>=M$4),1,0) -> 0 | N8: =IF(AND($E8<=N$4+6,$F8>=N$4),1,0) -> 1 | O8: =IF(AND($E8<=O$4+6,$F8>=O$4),1,0) -> 1 | P8: =IF(AND($E8<=P$4+6,$F8>=P$4),1,0) -> 1 | Q8: =IF(AND($E8<=Q$4+6,$F8>=Q$4),1,0) -> 1 | R8: =IF(AND($E8<=R$4+6,$F8>=R$4),1,0) -> 0 | S8: =IF(AND($E8<=S$4+6,$F8>=S$4),1,0) -> 0 | T8: =IF(AND($E8<=T$4+6,$F8>=T$4),1,0) -> 0 | ... AP8: =IF(AND($E8<=AP$4+6,$F8>=AP$4),1,0) -> 0
A9: M01 | B9: Dashboard | C9: Track A | D9: M02 Appointments | E9: =WORKDAY(F6,1,Holidays) -> 46391 | F9: =_xlfn.MAXIFS('Dev Task List'!$L:$L,'Dev Task List'!$B:$B,A9) -> 46401 | G9: =NETWORKDAYS(E9,F9,Holidays) -> 9 | H9: =COUNTIF('Dev Task List'!$B:$B,A9) -> 6 | I9: =SUMIF('Dev Task List'!$B:$B,A9,'Dev Task List'!$G:$G) -> 1 | J9: =COUNTIFS('Dev Task List'!$B:$B,A9,'Dev Task List'!$N:$N,"Done") -> 0 | K9: =IF(H9=0,0,J9/H9) -> 0 | M9: =IF(AND($E9<=M$4+6,$F9>=M$4),1,0) -> 0 | N9: =IF(AND($E9<=N$4+6,$F9>=N$4),1,0) -> 0 | O9: =IF(AND($E9<=O$4+6,$F9>=O$4),1,0) -> 0 | P9: =IF(AND($E9<=P$4+6,$F9>=P$4),1,0) -> 0 | Q9: =IF(AND($E9<=Q$4+6,$F9>=Q$4),1,0) -> 0 | R9: =IF(AND($E9<=R$4+6,$F9>=R$4),1,0) -> 0 | S9: =IF(AND($E9<=S$4+6,$F9>=S$4),1,0) -> 0 | T9: =IF(AND($E9<=T$4+6,$F9>=T$4),1,0) -> 0 | ... AP9: =IF(AND($E9<=AP$4+6,$F9>=AP$4),1,0) -> 0
A10: M04 | B10: Reports | C10: Track C | D10: M05 Account | E10: =WORKDAY(F8,1,Holidays) -> 46344 | F10: =_xlfn.MAXIFS('Dev Task List'!$L:$L,'Dev Task List'!$B:$B,A10) -> 46360 | G10: =NETWORKDAYS(E10,F10,Holidays) -> 12 | H10: =COUNTIF('Dev Task List'!$B:$B,A10) -> 6 | I10: =SUMIF('Dev Task List'!$B:$B,A10,'Dev Task List'!$G:$G) -> 6 | J10: =COUNTIFS('Dev Task List'!$B:$B,A10,'Dev Task List'!$N:$N,"Done") -> 0 | K10: =IF(H10=0,0,J10/H10) -> 0 | M10: =IF(AND($E10<=M$4+6,$F10>=M$4),1,0) -> 0 | N10: =IF(AND($E10<=N$4+6,$F10>=N$4),1,0) -> 0 | O10: =IF(AND($E10<=O$4+6,$F10>=O$4),1,0) -> 0 | P10: =IF(AND($E10<=P$4+6,$F10>=P$4),1,0) -> 0 | Q10: =IF(AND($E10<=Q$4+6,$F10>=Q$4),1,0) -> 1 | R10: =IF(AND($E10<=R$4+6,$F10>=R$4),1,0) -> 1 | S10: =IF(AND($E10<=S$4+6,$F10>=S$4),1,0) -> 1 | T10: =IF(AND($E10<=T$4+6,$F10>=T$4),1,0) -> 0 | ... AP10: =IF(AND($E10<=AP$4+6,$F10>=AP$4),1,0) -> 0
B11: Whole project | E11: =MIN(E5:E10) -> 46314 | F11: =MAX(F5:F10) -> 46457 | G11: =NETWORKDAYS(E11,F11,Holidays) -> 95 | H11: =SUM(H5:H10) -> 88 | I11: =SUM(I5:I10) -> 89 | J11: =SUM(J5:J10) -> 0 | K11: =IF(H11=0,0,J11/H11) -> 0 | M11: =IF(AND($E11<=M$4+6,$F11>=M$4),1,0) -> 1 | N11: =IF(AND($E11<=N$4+6,$F11>=N$4),1,0) -> 1 | O11: =IF(AND($E11<=O$4+6,$F11>=O$4),1,0) -> 1 | P11: =IF(AND($E11<=P$4+6,$F11>=P$4),1,0) -> 1 | Q11: =IF(AND($E11<=Q$4+6,$F11>=Q$4),1,0) -> 1 | R11: =IF(AND($E11<=R$4+6,$F11>=R$4),1,0) -> 1 | S11: =IF(AND($E11<=S$4+6,$F11>=S$4),1,0) -> 1 | T11: =IF(AND($E11<=T$4+6,$F11>=T$4),1,0) -> 1 | ... AP11: =IF(AND($E11<=AP$4+6,$F11>=AP$4),1,0) -> 0
A13: Planned start of a module can be overridden by typing a date over it; its tasks and later modules shift automatically.

Sheet Dev Task List
A1: Oralux Dentist Portal — Dev Task List
A2: One row per feature. Screens and Figma links come from https://www.figma.com/design/dAKa9xPhXAuRKat5jGS8Hx/Dentist. Dates come from Setup and Module Timeline.
A4: Task ID | B4: Module ID | C4: Module | D4: Sub-module | E4: Feature / Task | F4: Description | G4: Screens | H4: Screen names (Figma frames) | I4: Figma | J4: Est. days | K4: Planned start | L4: Planned end | M4: Assignee | N4: Status | O4: Actual start | P4: Actual end | Q4: Remarks
A5: M00.01.01 | B5: M00 | C5: Global / Shell | D5: Navigation & Layout | E5: Org / clinic switcher | F5: Clinic logo and name with 'Powered by oralux'; collapse-panel toggle. | G5: =COUNTIF('Screen List'!$B:$B,A5) -> 0 | H5: Shared UI — appears on other screens | J5: 1 | K5: =INDEX('Module Timeline'!$E:$E,MATCH(B5,'Module Timeline'!$A:$A,0)) -> 46314 | L5: =WORKDAY(K5,MAX(J5,1)-1,Holidays) -> 46314 | N5: Not started
A6: M00.01.02 | B6: M00 | C6: Global / Shell | D6: Navigation & Layout | E6: Sidebar menu | F6: Links to Dashboard, Appointments (Schedule), Patients and Reports. | G6: =COUNTIF('Screen List'!$B:$B,A6) -> 0 | H6: Shared UI — appears on other screens | J6: 2 | K6: =WORKDAY(L5,1,Holidays) -> 46315 | L6: =WORKDAY(K6,MAX(J6,1)-1,Holidays) -> 46316 | N6: Not started
A7: M00.01.03 | B7: M00 | C7: Global / Shell | D7: Navigation & Layout | E7: Global search (⌘K) | F7: Search patients and records from anywhere. | G7: =COUNTIF('Screen List'!$B:$B,A7) -> 0 | H7: Shared UI — appears on other screens | J7: 3 | K7: =WORKDAY(L6,1,Holidays) -> 46317 | L7: =WORKDAY(K7,MAX(J7,1)-1,Holidays) -> 46321 | N7: Not started
A8: M00.01.04 | B8: M00 | C8: Global / Shell | D8: Navigation & Layout | E8: Notifications | F8: Bell with unread count badge. | G8: =COUNTIF('Screen List'!$B:$B,A8) -> 0 | H8: Shared UI — appears on other screens | J8: 2 | K8: =WORKDAY(L7,1,Holidays) -> 46322 | L8: =WORKDAY(K8,MAX(J8,1)-1,Holidays) -> 46323 | N8: Not started
A9: M00.01.05 | B9: M00 | C9: Global / Shell | D9: Navigation & Layout | E9: User menu | F9: Logged-in dentist name, email and avatar; entry to Account. | G9: =COUNTIF('Screen List'!$B:$B,A9) -> 0 | H9: Shared UI — appears on other screens | J9: 1 | K9: =WORKDAY(L8,1,Holidays) -> 46324 | L9: =WORKDAY(K9,MAX(J9,1)-1,Holidays) -> 46324 | N9: Not started
A10: M01.01.01 | B10: M01 | C10: Dashboard | D10: Overview | E10: Greeting & day summary | F10: Greeting, date and number of appointments today. | G10: =COUNTIF('Screen List'!$B:$B,A10) -> 1 | H10: Dashboard — Dentist · Overview | I10: Open | J10: 1 | K10: =INDEX('Module Timeline'!$E:$E,MATCH(B10,'Module Timeline'!$A:$A,0)) -> 46391 | L10: =WORKDAY(K10,MAX(J10,1)-1,Holidays) -> 46391 | N10: Not started
A11: M01.01.02 | B11: M01 | C11: Dashboard | D11: Overview | E11: Today's schedule | F11: Timeline of today's appointments with status; next free slot; View all. | G11: =COUNTIF('Screen List'!$B:$B,A11) -> 0 | H11: Shared UI — appears on other screens | J11: 2 | K11: =WORKDAY(L10,1,Holidays) -> 46392 | L11: =WORKDAY(K11,MAX(J11,1)-1,Holidays) -> 46393 | N11: Not started
A12: M01.01.03 | B12: M01 | C12: Dashboard | D12: Overview | E12: Up next card | F12: Next patient in N minutes with procedure/tooth; View patient / Dental chart shortcuts. | G12: =COUNTIF('Screen List'!$B:$B,A12) -> 0 | H12: Shared UI — appears on other screens | J12: 1 | K12: =WORKDAY(L11,1,Holidays) -> 46394 | L12: =WORKDAY(K12,MAX(J12,1)-1,Holidays) -> 46394 | N12: Not started
A13: M01.01.04 | B13: M01 | C13: Dashboard | D13: Overview | E13: Appointment requests widget | F13: Pending requests with Accept / Decline. | G13: =COUNTIF('Screen List'!$B:$B,A13) -> 0 | H13: Shared UI — appears on other screens | J13: 2 | K13: =WORKDAY(L12,1,Holidays) -> 46395 | L13: =WORKDAY(K13,MAX(J13,1)-1,Holidays) -> 46398 | N13: Not started
A14: M01.01.05 | B14: M01 | C14: Dashboard | D14: Overview | E14: Patients seen per month | F14: Bar chart of the last 6 months with % change. | G14: =COUNTIF('Screen List'!$B:$B,A14) -> 0 | H14: Shared UI — appears on other screens | J14: 2 | K14: =WORKDAY(L13,1,Holidays) -> 46399 | L14: =WORKDAY(K14,MAX(J14,1)-1,Holidays) -> 46400 | N14: Not started
A15: M01.01.06 | B15: M01 | C15: Dashboard | D15: Overview | E15: Recent patients | F15: Patients from the most recent visits. | G15: =COUNTIF('Screen List'!$B:$B,A15) -> 0 | H15: Shared UI — appears on other screens | J15: 1 | K15: =WORKDAY(L14,1,Holidays) -> 46401 | L15: =WORKDAY(K15,MAX(J15,1)-1,Holidays) -> 46401 | N15: Not started
A16: M02.01.01 | B16: M02 | C16: Appointments | D16: Calendar Views | E16: Day view | F16: Hourly timeline per dentist with status counts, Next up, and the requests panel. | G16: =COUNTIF('Screen List'!$B:$B,A16) -> 2 | H16: Appointments - Day Appointments - Day | I16: Open | J16: 4 | K16: =INDEX('Module Timeline'!$E:$E,MATCH(B16,'Module Timeline'!$A:$A,0)) -> 46325 | L16: =WORKDAY(K16,MAX(J16,1)-1,Holidays) -> 46331 | N16: Not started
A17: M02.01.02 | B17: M02 | C17: Appointments | D17: Calendar Views | E17: Date filter | F17: Date picker to jump to a specific day. | G17: =COUNTIF('Screen List'!$B:$B,A17) -> 1 | H17: Appointments - Day · Date filter | I17: Open | J17: 1 | K17: =WORKDAY(L16,1,Holidays) -> 46332 | L17: =WORKDAY(K17,MAX(J17,1)-1,Holidays) -> 46332 | N17: Not started
A18: M02.01.03 | B18: M02 | C18: Appointments | D18: Calendar Views | E18: Week view | F18: Week grid with appointment counts per day. | G18: =COUNTIF('Screen List'!$B:$B,A18) -> 1 | H18: Appointments - Week | I18: Open | J18: 3 | K18: =WORKDAY(L17,1,Holidays) -> 46335 | L18: =WORKDAY(K18,MAX(J18,1)-1,Holidays) -> 46337 | N18: Not started
A19: M02.01.04 | B19: M02 | C19: Appointments | D19: Calendar Views | E19: Month view | F19: Month grid of appointments. | G19: =COUNTIF('Screen List'!$B:$B,A19) -> 1 | H19: Appointments - Month | I19: Open | J19: 3 | K19: =WORKDAY(L18,1,Holidays) -> 46338 | L19: =WORKDAY(K19,MAX(J19,1)-1,Holidays) -> 46342 | N19: Not started
A20: M02.01.05 | B20: M02 | C20: Appointments | D20: Calendar Views | E20: Filters & toolbar | F20: Today, treatment filter, chair filter, Day/Week/Month toggle, Full screen, New appointment. | G20: =COUNTIF('Screen List'!$B:$B,A20) -> 0 | H20: Shared UI — appears on other screens | J20: 2 | K20: =WORKDAY(L19,1,Holidays) -> 46343 | L20: =WORKDAY(K20,MAX(J20,1)-1,Holidays) -> 46344 | N20: Not started
A21: M02.01.06 | B21: M02 | C21: Appointments | D21: Calendar Views | E21: Status legend & summary | F21: Confirmed, Pending, Rescheduled, Cancelled, Completed, In chair, Checked in, No-show. | G21: =COUNTIF('Screen List'!$B:$B,A21) -> 0 | H21: Shared UI — appears on other screens | J21: 1 | K21: =WORKDAY(L20,1,Holidays) -> 46345 | L21: =WORKDAY(K21,MAX(J21,1)-1,Holidays) -> 46345 | N21: Not started
A22: M02.02.01 | B22: M02 | C22: Appointments | D22: Appointment Details | E22: View details | F22: Appointment details modal opened from the calendar. | G22: =COUNTIF('Screen List'!$B:$B,A22) -> 1 | H22: Appointments - Day · Details · Modal | I22: Open | J22: 2 | K22: =WORKDAY(L21,1,Holidays) -> 46346 | L22: =WORKDAY(K22,MAX(J22,1)-1,Holidays) -> 46349 | N22: Not started
A23: M02.02.02 | B23: M02 | C23: Appointments | D23: Appointment Details | E23: Status states | F23: Details modal for Pending, Confirmed, Rescheduled, Cancelled and Completed. | G23: =COUNTIF('Screen List'!$B:$B,A23) -> 6 | H23: Details modal · Pending Details modal · Confirmed Details modal · Rescheduled Details modal · Cancelled Details modal · Completed Details modal · Completed | I23: Open | J23: 3 | K23: =WORKDAY(L22,1,Holidays) -> 46350 | L23: =WORKDAY(K23,MAX(J23,1)-1,Holidays) -> 46352 | N23: Not started
A24: M02.02.03 | B24: M02 | C24: Appointments | D24: Appointment Details | E24: Reschedule | F24: Pick a new date and time for an appointment. | G24: =COUNTIF('Screen List'!$B:$B,A24) -> 1 | H24: Details modal · Reschedule | I24: Open | J24: 2 | K24: =WORKDAY(L23,1,Holidays) -> 46353 | L24: =WORKDAY(K24,MAX(J24,1)-1,Holidays) -> 46357 | N24: Not started
A25: M02.02.04 | B25: M02 | C25: Appointments | D25: Appointment Details | E25: Cancel appointment | F25: Confirmation dialog for cancelling. | G25: =COUNTIF('Screen List'!$B:$B,A25) -> 1 | H25: Cancel dialog | I25: Open | J25: 1 | K25: =WORKDAY(L24,1,Holidays) -> 46358 | L25: =WORKDAY(K25,MAX(J25,1)-1,Holidays) -> 46358 | N25: Not started
A26: M02.02.05 | B26: M02 | C26: Appointments | D26: Appointment Details | E26: More actions menu | F26: Overflow actions on a confirmed appointment. | G26: =COUNTIF('Screen List'!$B:$B,A26) -> 1 | H26: Details modal · Confirmed · More action open | I26: Open | J26: 1 | K26: =WORKDAY(L25,1,Holidays) -> 46359 | L26: =WORKDAY(K26,MAX(J26,1)-1,Holidays) -> 46359 | N26: Not started
A27: M02.02.06 | B27: M02 | C27: Appointments | D27: Appointment Details | E27: Change procedure | F27: Multi-select to change the booked procedures. | G27: =COUNTIF('Screen List'!$B:$B,A27) -> 1 | H27: Details modal · Change procedure · Multi-select | I27: Open | J27: 2 | K27: =WORKDAY(L26,1,Holidays) -> 46360 | L27: =WORKDAY(K27,MAX(J27,1)-1,Holidays) -> 46363 | N27: Not started
A28: M02.02.07 | B28: M02 | C28: Appointments | D28: Appointment Details | E28: Last visit history | F28: Expandable summary of the patient's last visit. | G28: =COUNTIF('Screen List'!$B:$B,A28) -> 1 | H28: Details modal · Last visit (expanded) | I28: Open | J28: 1 | K28: =WORKDAY(L27,1,Holidays) -> 46365 | L28: =WORKDAY(K28,MAX(J28,1)-1,Holidays) -> 46365 | N28: Not started
A29: M02.03.01 | B29: M02 | C29: Appointments | D29: Add Appointment | E29: Select patient | F29: Search and pick a patient (empty, dropdown and selected states). | G29: =COUNTIF('Screen List'!$B:$B,A29) -> 3 | H29: Appointments - Add appointment · Select patient (1 empty) Appointments - Add appointment · Select patient (2 dropdown) Appointments - Add appointment · Select patient (3 selected) | I29: Open | J29: 2 | K29: =WORKDAY(L28,1,Holidays) -> 46366 | L29: =WORKDAY(K29,MAX(J29,1)-1,Holidays) -> 46367 | N29: Not started
A30: M02.03.02 | B30: M02 | C30: Appointments | D30: Add Appointment | E30: Select procedure & schedule | F30: Choose procedures, dentist, date and time. | G30: =COUNTIF('Screen List'!$B:$B,A30) -> 1 | H30: Appointments - Add appointment | I30: Open | J30: 3 | K30: =WORKDAY(L29,1,Holidays) -> 46370 | L30: =WORKDAY(K30,MAX(J30,1)-1,Holidays) -> 46372 | N30: Not started
A31: M02.03.03 | B31: M02 | C31: Appointments | D31: Add Appointment | E31: All procedures list | F31: Browse the full procedure catalogue. | G31: =COUNTIF('Screen List'!$B:$B,A31) -> 1 | H31: Appointments - Add appointment · All procedures | I31: Open | J31: 1 | K31: =WORKDAY(L30,1,Holidays) -> 46373 | L31: =WORKDAY(K31,MAX(J31,1)-1,Holidays) -> 46373 | N31: Not started
A32: M02.03.04 | B32: M02 | C32: Appointments | D32: Add Appointment | E32: Review & confirm | F32: Summary before booking. | G32: =COUNTIF('Screen List'!$B:$B,A32) -> 1 | H32: Appointments - Add appointment · Review & confirm | I32: Open | J32: 1 | K32: =WORKDAY(L31,1,Holidays) -> 46374 | L32: =WORKDAY(K32,MAX(J32,1)-1,Holidays) -> 46374 | N32: Not started
A33: M02.03.05 | B33: M02 | C33: Appointments | D33: Add Appointment | E33: Booking confirmation | F33: Success state after booking. | G33: =COUNTIF('Screen List'!$B:$B,A33) -> 1 | H33: Appointments - Add appointment · Booked | I33: Open | J33: 1 | K33: =WORKDAY(L32,1,Holidays) -> 46377 | L33: =WORKDAY(K33,MAX(J33,1)-1,Holidays) -> 46377 | N33: Not started
... A35: M02.04.02 | B35: M02 | C35: Appointments | D35: Appointment Requests | E35: Request details | F35: Full details of a single request. | G35: =COUNTIF('Screen List'!$B:$B,A35) -> 1 | H35: Appointments — Calendar - Requests drawer · View details | I35: Open | J35: 1 | K35: =WORKDAY(L34,1,Holidays) -> 46385 | L35: =WORKDAY(K35,MAX(J35,1)-1,Holidays) -> 46385 | N35: Not started
A36: M03.01.01 | B36: M03 | C36: Patients | D36: Patient List | E36: Patient list | F36: Table of name, dentist, last procedure, last visit, balance, status; search; pagination. | G36: =COUNTIF('Screen List'!$B:$B,A36) -> 1 | H36: Patients — List | I36: Open | J36: 3 | K36: =INDEX('Module Timeline'!$E:$E,MATCH(B36,'Module Timeline'!$A:$A,0)) -> 46325 | L36: =WORKDAY(K36,MAX(J36,1)-1,Holidays) -> 46330 | N36: Not started
A37: M03.02.01 | B37: M03 | C37: Patients | D37: Add Patient | E37: Add patient form | F37: Photo, patient information, contact details, tags and notes. | G37: =COUNTIF('Screen List'!$B:$B,A37) -> 1 | H37: Patients — Add patient · Modal · v2 (field list) · Desktop | I37: Open | J37: 3 | K37: =WORKDAY(L36,1,Holidays) -> 46331 | L37: =WORKDAY(K37,MAX(J37,1)-1,Holidays) -> 46335 | N37: Not started
A38: M03.02.02 | B38: M03 | C38: Patients | D38: Add Patient | E38: Add success | F38: Confirmation after the record is created. | G38: =COUNTIF('Screen List'!$B:$B,A38) -> 1 | H38: Patients — Add patient · Success · Desktop | I38: Open | J38: 1 | K38: =WORKDAY(L37,1,Holidays) -> 46336 | L38: =WORKDAY(K38,MAX(J38,1)-1,Holidays) -> 46336 | N38: Not started
A39: M03.02.03 | B39: M03 | C39: Patients | D39: Add Patient | E39: Duplicate detection | F39: Compare the new entry with a matching existing record (% match). | G39: =COUNTIF('Screen List'!$B:$B,A39) -> 1 | H39: Patients — Add patient · Duplicate found · v1 (comparison) · Desktop | I39: Open | J39: 3 | K39: =WORKDAY(L38,1,Holidays) -> 46337 | L39: =WORKDAY(K39,MAX(J39,1)-1,Holidays) -> 46339 | N39: Not started
A40: M03.02.04 | B40: M03 | C40: Patients | D40: Add Patient | E40: Merge records | F40: Confirm merging with the existing record. | G40: =COUNTIF('Screen List'!$B:$B,A40) -> 1 | H40: Patients — Add patient · Merge confirmation · Desktop | I40: Open | J40: 2 | K40: =WORKDAY(L39,1,Holidays) -> 46342 | L40: =WORKDAY(K40,MAX(J40,1)-1,Holidays) -> 46343 | N40: Not started
A41: M03.02.05 | B41: M03 | C41: Patients | D41: Add Patient | E41: Merge success | F41: Confirmation after merging. | G41: =COUNTIF('Screen List'!$B:$B,A41) -> 1 | H41: Patients — Add patient · Merge success · Desktop | I41: Open | J41: 1 | K41: =WORKDAY(L40,1,Holidays) -> 46344 | L41: =WORKDAY(K41,MAX(J41,1)-1,Holidays) -> 46344 | N41: Not started
A42: M03.03.01 | B42: M03 | C42: Patients | D42: Patient Details · Header | E42: Patient summary | F42: ID, name, status, member since, age, DOB, gender, primary dentist, last visit. | G42: =COUNTIF('Screen List'!$B:$B,A42) -> 0 | H42: Shared UI — appears on other screens | J42: 2 | K42: =WORKDAY(L41,1,Holidays) -> 46345 | L42: =WORKDAY(K42,MAX(J42,1)-1,Holidays) -> 46346 | N42: Not started
...

Sheet Screen List
A1: Screen List
A2: Every Figma frame and the task it belongs to.
A4: # | B4: Task ID | C4: Module | D4: Feature / Task | E4: Figma frame name | F4: Figma
A5: 1 | B5: M01.01.01 | C5: Dashboard | D5: Greeting & day summary | E5: Dashboard — Dentist · Overview | F5: Open
A6: 2 | B6: M02.01.01 | C6: Appointments | D6: Day view | E6: Appointments - Day | F6: Open
A7: 3 | B7: M02.01.01 | C7: Appointments | D7: Day view | E7: Appointments - Day | F7: Open
A8: 4 | B8: M02.01.02 | C8: Appointments | D8: Date filter | E8: Appointments - Day · Date filter | F8: Open
A9: 5 | B9: M02.01.03 | C9: Appointments | D9: Week view | E9: Appointments - Week | F9: Open
A10: 6 | B10: M02.01.04 | C10: Appointments | D10: Month view | E10: Appointments - Month | F10: Open
A11: 7 | B11: M02.02.01 | C11: Appointments | D11: View details | E11: Appointments - Day · Details · Modal | F11: Open
A12: 8 | B12: M02.02.02 | C12: Appointments | D12: Status states | E12: Details modal · Pending | F12: Open
A13: 9 | B13: M02.02.02 | C13: Appointments | D13: Status states | E13: Details modal · Confirmed | F13: Open
A14: 10 | B14: M02.02.02 | C14: Appointments | D14: Status states | E14: Details modal · Rescheduled | F14: Open
A15: 11 | B15: M02.02.02 | C15: Appointments | D15: Status states | E15: Details modal · Cancelled | F15: Open
A16: 12 | B16: M02.02.02 | C16: Appointments | D16: Status states | E16: Details modal · Completed | F16: Open
... A93: 89 | B93: M05.02.05 | C93: Account | D93: Remove signature | E93: Profile — Account · My signature · Remove confirmation | F93: Open

Sheet Setup
A1: Project Setup
A2: Edit the blue cells. All dates in the plan recalculate from these.
A4: Project start date | B4: 46314 | C4: Monday, Oct 19, 2026 is a placeholder. Set it to the real kickoff date.
A6: Legend
A7: Blue text | C7: Input you can change (start date, est. days, holidays). Typing a date over a Start formula pins that task.
A8: Yellow fill | C8: For the dev team to fill in (assignee, status, actual dates, remarks).
A9: Black text | C9: Formula. Don't type over it unless you mean to override it.
A11: Scheduling rules
A12: 1. | B12: Dates skip weekends and the holidays below (WORKDAY).
A13: 2. | B13: Inside a module, tasks run one after another: each starts the working day after the previous one ends.
A14: 3. | B14: Modules run on 3 parallel tracks after Global / Shell: A = Appointments → Dashboard, B = Patients, C = Account → Reports.
A15: 4. | B15: Est. days are placeholder estimates for one developer, based on screen count and complexity. The dev team should replace them.
A17: Holidays (non-working days) | C17: Source: Philippine regular and special non-working days; verify against the official proclamation for 2026 and 2027.
A18: Date | B18: Holiday
A19: 46328 | B19: All Souls' Day (special non-working, verify)
A20: 46356 | B20: Bonifacio Day
A21: 46364 | B21: Feast of the Immaculate Conception
A22: 46380 | B22: Christmas Eve
A23: 46381 | B23: Christmas Day
A24: 46386 | B24: Rizal Day
A25: 46387 | B25: Last Day of the Year
A26: 46388 | B26: New Year's Day
A27: 46443 | B27: EDSA Revolution Anniversary (verify)
A28: 46471 | B28: Maundy Thursday
A29: 46472 | B29: Good Friday
A30: 46486 | B30: Araw ng Kagitingan
