Workbook

Sheet Module Map
A1: Oralux (Dentist) — Module Map
A2: Source: Figma file 'Dentist' (dAKa9xPhXAuRKat5jGS8Hx), Page 1 · 66 desktop frames (1440px). Node 1:4970 holds 5 status variants.
A4: # | B4: Module | C4: Sub-module | D4: Screen / State | E4: Type | F4: Figma Node ID | G4: Figma Link | H4: Notes
A5: 1 | B5: Dashboard | C5: Overview | D5: Dashboard — Dentist · Overview | E5: Page | F5: 1:26962 | G5: Open in Figma | H5: Greeting, 4 KPI cards, today's schedule, Up next, appointment requests (Accept/Decline), patients-per-month chart, recent patients
A6: 2 | B6: Appointments | C6: Calendar views | D6: Day view | E6: Page | F6: 1:1192 | G6: Open in Figma
A7: 3 | B7: Appointments | C7: Calendar views | D7: Day view (alternate) | E7: Page | F7: 1:1658 | G7: Open in Figma
A8: 4 | B8: Appointments | C8: Calendar views | D8: Day view · Date filter | E8: State | F8: 1:3840 | G8: Open in Figma | H8: Date picker / filter open
A9: 5 | B9: Appointments | C9: Calendar views | D9: Week view | E9: Page | F9: 1:2124 | G9: Open in Figma
A10: 6 | B10: Appointments | C10: Calendar views | D10: Month view | E10: Page | F10: 1:2911 | G10: Open in Figma
A11: 7 | B11: Appointments | C11: Appointment details | D11: Day · Details modal | E11: Modal | F11: 1:4408 | G11: Open in Figma | H11: Details card over day view
A12: 8 | B12: Appointments | C12: Appointment details | D12: Details modal · Pending | E12: State | F12: 1:4970 | G12: Open in Figma | H12: Actions: Reschedule, Cancel, Confirm
A13: 9 | B13: Appointments | C13: Appointment details | D13: Details modal · Confirmed | E13: State | F13: 1:4970 | G13: Open in Figma | H13: Actions: More, Completed, Bill Patient
A14: 10 | B14: Appointments | C14: Appointment details | D14: Details modal · Rescheduled | E14: State | F14: 1:4970 | G14: Open in Figma | H14: Actions: Reschedule, Cancel, Confirm
A15: 11 | B15: Appointments | C15: Appointment details | D15: Details modal · Cancelled | E15: State | F15: 1:4970 | G15: Open in Figma | H15: Actions: Close, Rebook appointment
A16: 12 | B16: Appointments | C16: Appointment details | D16: Details modal · Completed | E16: State | F16: 1:4970 | G16: Open in Figma | H16: Actions: View record, Book follow-up, Bill Patient
A17: 13 | B17: Appointments | C17: Add appointment | D17: Select patient · Empty | E17: Modal | F17: 1:8117 | G17: Open in Figma | H17: Step 1
A18: 14 | B18: Appointments | C18: Add appointment | D18: Select patient · Dropdown | E18: State | F18: 1:9150 | G18: Open in Figma | H18: Step 1
A19: 15 | B19: Appointments | C19: Add appointment | D19: Select patient · Selected | E19: State | F19: 1:9689 | G19: Open in Figma | H19: Step 1
A20: 16 | B20: Appointments | C20: Add appointment | D20: Add appointment form | E20: Page | F20: 1:6024 | G20: Open in Figma | H20: Step 2
A21: 17 | B21: Appointments | C21: Add appointment | D21: All procedures | E21: Modal | F21: 1:7516 | G21: Open in Figma | H21: Step 2 – procedure picker
A22: 18 | B22: Appointments | C22: Add appointment | D22: Review & confirm | E22: Modal | F22: 1:10207 | G22: Open in Figma | H22: Step 3
A23: 19 | B23: Appointments | C23: Add appointment | D23: Booked | E23: Modal | F23: 1:8618 | G23: Open in Figma | H23: Step 4 – success
A24: 20 | B24: Appointments | C24: Appointment requests | D24: Requests drawer | E24: Drawer | F24: 1:429 | G24: Open in Figma
A25: 21 | B25: Appointments | C25: Appointment requests | D25: Request details | E25: Modal | F25: 1:10773 | G25: Open in Figma
A26: 22 | B26: Patients | C26: Patient list | D26: Patients — List | E26: Page | F26: 1:11627 | G26: Open in Figma
A27: 23 | B27: Patients | C27: Details · General | D27: General | E27: Page | F27: 1:12020 | G27: Open in Figma | H27: Contact, emergency contact, other info, insurance, membership, notes, outstanding balance, recent activity
A28: 24 | B28: Patients | C28: Details · General | D28: General · Edit | E28: State | F28: 1:12291 | G28: Open in Figma
A29: 25 | B29: Patients | C29: Details · Medical History | D29: Medical History | E29: Page | F29: 1:12581 | G29: Open in Figma
A30: 26 | B30: Patients | C30: Details · Medical History | D30: Medical History · Edit | E30: State | F30: 1:12879 | G30: Open in Figma
A31: 27 | B31: Patients | C31: Details · Dental Record Chart | D31: Chart · Many findings · Collapsed | E31: Page | F31: 1:13779 | G31: Open in Figma
A32: 28 | B32: Patients | C32: Details · Dental Record Chart | D32: Chart · Many findings · Expanded | E32: State | F32: 1:13210 | G32: Open in Figma
A33: 29 | B33: Patients | C33: Details · Dental Record Chart | D33: Chart · Full screen | E33: Page | F33: 1:14275 | G33: Open in Figma | H33: No sidebar – full-screen view
A34: 30 | B34: Patients | C34: Details · Transaction Record | D34: Transaction Record | E34: Page | F34: 1:14602 | G34: Open in Figma
A35: 31 | B35: Patients | C35: Details · Statement of Account | D35: Statement of Account | E35: Page | F35: 1:15053 | G35: Open in Figma
A36: 32 | B36: Patients | C36: Details · Docs | D36: Docs list | E36: Page | F36: 1:15418 | G36: Open in Figma
A37: 33 | B37: Patients | C37: Details · Docs | D37: Docs · Row actions menu | E37: State | F37: 1:19681 | G37: Open in Figma
A38: 34 | B38: Patients | C38: Details · Docs | D38: Add document · 1 Choose type | E38: Modal | F38: 1:15749 | G38: Open in Figma
A39: 35 | B39: Patients | C39: Details · Docs | D39: Add document · 2 Prescription | E39: Modal | F39: 1:16156 | G39: Open in Figma
A40: 36 | B40: Patients | C40: Details · Docs | D40: Add document · 3 Dental Certificate | E40: Modal | F40: 1:16589 | G40: Open in Figma
A41: 37 | B41: Patients | C41: Details · Docs | D41: Add document · 4 Informed Consent | E41: Modal | F41: 1:17050 | G41: Open in Figma
...

Sheet Summary
A1: Screen count by module
A3: Module | B3: Page | C3: State | D3: Modal | E3: Drawer | F3: Dialog | G3: Total
A4: Dashboard | B4: =COUNTIFS('Module Map'!$B$5:$B$74,$A4,'Module Map'!$E$5:$E$74,B$3) -> 1 | C4: =COUNTIFS('Module Map'!$B$5:$B$74,$A4,'Module Map'!$E$5:$E$74,C$3) -> 0 | D4: =COUNTIFS('Module Map'!$B$5:$B$74,$A4,'Module Map'!$E$5:$E$74,D$3) -> 0 | E4: =COUNTIFS('Module Map'!$B$5:$B$74,$A4,'Module Map'!$E$5:$E$74,E$3) -> 0 | F4: =COUNTIFS('Module Map'!$B$5:$B$74,$A4,'Module Map'!$E$5:$E$74,F$3) -> 0 | G4: =SUM(B4:F4) -> 1
A5: Appointments | B5: =COUNTIFS('Module Map'!$B$5:$B$74,$A5,'Module Map'!$E$5:$E$74,B$3) -> 5 | C5: =COUNTIFS('Module Map'!$B$5:$B$74,$A5,'Module Map'!$E$5:$E$74,C$3) -> 8 | D5: =COUNTIFS('Module Map'!$B$5:$B$74,$A5,'Module Map'!$E$5:$E$74,D$3) -> 6 | E5: =COUNTIFS('Module Map'!$B$5:$B$74,$A5,'Module Map'!$E$5:$E$74,E$3) -> 1 | F5: =COUNTIFS('Module Map'!$B$5:$B$74,$A5,'Module Map'!$E$5:$E$74,F$3) -> 0 | G5: =SUM(B5:F5) -> 20
A6: Patients | B6: =COUNTIFS('Module Map'!$B$5:$B$74,$A6,'Module Map'!$E$5:$E$74,B$3) -> 11 | C6: =COUNTIFS('Module Map'!$B$5:$B$74,$A6,'Module Map'!$E$5:$E$74,C$3) -> 7 | D6: =COUNTIFS('Module Map'!$B$5:$B$74,$A6,'Module Map'!$E$5:$E$74,D$3) -> 13 | E6: =COUNTIFS('Module Map'!$B$5:$B$74,$A6,'Module Map'!$E$5:$E$74,E$3) -> 0 | F6: =COUNTIFS('Module Map'!$B$5:$B$74,$A6,'Module Map'!$E$5:$E$74,F$3) -> 1 | G6: =SUM(B6:F6) -> 32
A7: Reports | B7: =COUNTIFS('Module Map'!$B$5:$B$74,$A7,'Module Map'!$E$5:$E$74,B$3) -> 4 | C7: =COUNTIFS('Module Map'!$B$5:$B$74,$A7,'Module Map'!$E$5:$E$74,C$3) -> 2 | D7: =COUNTIFS('Module Map'!$B$5:$B$74,$A7,'Module Map'!$E$5:$E$74,D$3) -> 0 | E7: =COUNTIFS('Module Map'!$B$5:$B$74,$A7,'Module Map'!$E$5:$E$74,E$3) -> 0 | F7: =COUNTIFS('Module Map'!$B$5:$B$74,$A7,'Module Map'!$E$5:$E$74,F$3) -> 0 | G7: =SUM(B7:F7) -> 6
A8: Profile / Account | B8: =COUNTIFS('Module Map'!$B$5:$B$74,$A8,'Module Map'!$E$5:$E$74,B$3) -> 2 | C8: =COUNTIFS('Module Map'!$B$5:$B$74,$A8,'Module Map'!$E$5:$E$74,C$3) -> 1 | D8: =COUNTIFS('Module Map'!$B$5:$B$74,$A8,'Module Map'!$E$5:$E$74,D$3) -> 7 | E8: =COUNTIFS('Module Map'!$B$5:$B$74,$A8,'Module Map'!$E$5:$E$74,E$3) -> 0 | F8: =COUNTIFS('Module Map'!$B$5:$B$74,$A8,'Module Map'!$E$5:$E$74,F$3) -> 1 | G8: =SUM(B8:F8) -> 11
A9: Total | B9: =SUM(B4:B8) -> 23 | C9: =SUM(C4:C8) -> 18 | D9: =SUM(D4:D8) -> 26 | E9: =SUM(E4:E8) -> 1 | F9: =SUM(F4:F8) -> 2 | G9: =SUM(G4:G8) -> 70
A11: Type legend: Page = full screen · State = variant of a screen (empty/edit/open) · Modal/Drawer/Dialog = overlay

Sheet Sub-modules
A1: Module | B1: Sub-module | C1: Screens / States
A2: Dashboard | B2: Overview | C2: =COUNTIFS('Module Map'!$B$5:$B$74,A2,'Module Map'!$C$5:$C$74,B2) -> 1
A3: Appointments | B3: Calendar views | C3: =COUNTIFS('Module Map'!$B$5:$B$74,A3,'Module Map'!$C$5:$C$74,B3) -> 5
A4: Appointments | B4: Appointment details | C4: =COUNTIFS('Module Map'!$B$5:$B$74,A4,'Module Map'!$C$5:$C$74,B4) -> 6
A5: Appointments | B5: Add appointment | C5: =COUNTIFS('Module Map'!$B$5:$B$74,A5,'Module Map'!$C$5:$C$74,B5) -> 7
A6: Appointments | B6: Appointment requests | C6: =COUNTIFS('Module Map'!$B$5:$B$74,A6,'Module Map'!$C$5:$C$74,B6) -> 2
A7: Patients | B7: Patient list | C7: =COUNTIFS('Module Map'!$B$5:$B$74,A7,'Module Map'!$C$5:$C$74,B7) -> 1
A8: Patients | B8: Details · General | C8: =COUNTIFS('Module Map'!$B$5:$B$74,A8,'Module Map'!$C$5:$C$74,B8) -> 2
A9: Patients | B9: Details · Medical History | C9: =COUNTIFS('Module Map'!$B$5:$B$74,A9,'Module Map'!$C$5:$C$74,B9) -> 2
A10: Patients | B10: Details · Dental Record Chart | C10: =COUNTIFS('Module Map'!$B$5:$B$74,A10,'Module Map'!$C$5:$C$74,B10) -> 3
A11: Patients | B11: Details · Transaction Record | C11: =COUNTIFS('Module Map'!$B$5:$B$74,A11,'Module Map'!$C$5:$C$74,B11) -> 1
A12: Patients | B12: Details · Statement of Account | C12: =COUNTIFS('Module Map'!$B$5:$B$74,A12,'Module Map'!$C$5:$C$74,B12) -> 1
A13: Patients | B13: Details · Docs | C13: =COUNTIFS('Module Map'!$B$5:$B$74,A13,'Module Map'!$C$5:$C$74,B13) -> 11
... A18: Profile / Account | B18: My signature | C18: =COUNTIFS('Module Map'!$B$5:$B$74,A18,'Module Map'!$C$5:$C$74,B18) -> 5

Sheet Shared Components
A1: Component | B1: Where used | C1: Notes
A2: Sidebar · Dark | B2: All screens | C2: Org switcher, Menu (Dashboard, Appointments, Patients, Reports + sub items), user card, logout
A3: Top bar | B3: All screens | C3: Breadcrumb, global search (⌘K), notifications bell with badge
A4: KPI card | B4: Dashboard | C4: Report / KPI card instance
A5: Buttons / Toolbar button | B5: All modules | C5: Report / Button, Report / Toolbar button
A6: Tabs | B6: Patient details, Add photos, Add signature | C6: 7 patient tabs; Draw/Type/Upload; From patient photos/Upload new
A7: Data table | B7: Patients list, Reports, Transactions | C7: Search, filters, column filter popover
A8: Status badge | B8: Appointments, Dashboard, Reports | C8: Pending, Confirmed, Rescheduled, Cancelled, Completed, Done
A9: Modal + Overlay/Scrim | B9: All modules
A10: Drawer | B10: Appointment requests
A11: Dropdown menu | B11: Reports, Select patient | C11: Dropdown menu · Status, Patient dropdown
A12: Row actions menu | B12: Docs | C12: Menu · Row actions
A13: File / photo uploader | B13: Docs, Images, Signature
A14: Signature pad | B14: Docs (Privacy Notice), My signature | C14: Tap to sign / Draw
A15: Photo viewer | B15: Images | C15: View, edit details, delete
A16: Confirmation dialog | B16: Images, My signature | C16: Delete photo, Remove signature
